[08/Sep/2020 09:46:54] "GET / HTTP/1.1" 200 7547
Not Found: /favicon.ico
[08/Sep/2020 09:46:54] "GET /favicon.ico HTTP/1.1" 404 2161
[08/Sep/2020 09:47:23] "GET / HTTP/1.1" 200 7547
[08/Sep/2020 09:47:23] "GET /static/table.css HTTP/1.1" 200 5445
[08/Sep/2020 09:47:23] "GET /static/js/jquery.date_input.pack.js HTTP/1.1" 200 10074
Not Found: /favicon.ico
[08/Sep/2020 09:47:24] "GET /favicon.ico HTTP/1.1" 404 2161
[08/Sep/2020 10:39:26] "GET /? HTTP/1.1" 200 7547
[08/Sep/2020 10:49:48] "GET / HTTP/1.1" 200 7547
[08/Sep/2020 10:49:48] "GET /static/table.css HTTP/1.1" 200 5445
[08/Sep/2020 10:49:48] "GET /static/js/jquery.date_input.pack.js HTTP/1.1" 200 10074
Not Found: /favicon.ico
[08/Sep/2020 10:49:49] "GET /favicon.ico HTTP/1.1" 404 2161
Performing system checks...

System check identified no issues (0 silenced).
September 08, 2020 - 09:45:59
Django version 1.10.2, using settings 'logAnalyse.settings'
Starting development server at http://0.0.0.0:9000/
Quit the server with CONTROL-C.
Performing system checks...

System check identified no issues (0 silenced).
September 09, 2020 - 02:49:41
Django version 1.10.2, using settings 'logAnalyse.settings'
Starting development server at http://0.0.0.0:9000/
Quit the server with CONTROL-C.
Unhandled exception in thread started by <function wrapper at 0x7f3c83ae60c8>
Performing system checks...

Traceback (most recent call last):
  File "/usr/lib/python2.7/site-packages/django/utils/autoreload.py", line 226, in wrapper
    fn(*args, **kwargs)
  File "/usr/lib/python2.7/site-packages/django/core/management/commands/runserver.py", line 121, in inner_run
    self.check(display_num_errors=True)
  File "/usr/lib/python2.7/site-packages/django/core/management/base.py", line 374, in check
    include_deployment_checks=include_deployment_checks,
  File "/usr/lib/python2.7/site-packages/django/core/management/base.py", line 361, in _run_checks
    return checks.run_checks(**kwargs)
  File "/usr/lib/python2.7/site-packages/django/core/checks/registry.py", line 81, in run_checks
    new_errors = check(app_configs=app_configs)
  File "/usr/lib/python2.7/site-packages/django/core/checks/urls.py", line 14, in check_url_config
    return check_resolver(resolver)
  File "/usr/lib/python2.7/site-packages/django/core/checks/urls.py", line 24, in check_resolver
    for pattern in resolver.url_patterns:
  File "/usr/lib/python2.7/site-packages/django/utils/functional.py", line 35, in __get__
    res = instance.__dict__[self.name] = self.func(instance)
  File "/usr/lib/python2.7/site-packages/django/urls/resolvers.py", line 313, in url_patterns
    patterns = getattr(self.urlconf_module, "urlpatterns", self.urlconf_module)
  File "/usr/lib/python2.7/site-packages/django/utils/functional.py", line 35, in __get__
    res = instance.__dict__[self.name] = self.func(instance)
  File "/usr/lib/python2.7/site-packages/django/urls/resolvers.py", line 306, in urlconf_module
    return import_module(self.urlconf_name)
  File "/usr/lib64/python2.7/importlib/__init__.py", line 37, in import_module
    __import__(name)
  File "/home/logAnalyse/logAnalyse/logAnalyse/urls.py", line 19, in <module>
    from . import gitlog
  File "/home/logAnalyse/logAnalyse/logAnalyse/gitlog.py", line 273
    log = r.git.log('--pretty=format:|%H|%h|%ae|%an|%ce|%cn|%at|%ad|', "--numstat", "--after='+"last_time"+'", "-n 1000",skip)
                                                                                                        ^
SyntaxError: invalid syntax
Unhandled exception in thread started by <function wrapper at 0x7fac0b4e5488>
Performing system checks...

Traceback (most recent call last):
  File "/usr/lib/python2.7/site-packages/django/utils/autoreload.py", line 226, in wrapper
    fn(*args, **kwargs)
  File "/usr/lib/python2.7/site-packages/django/core/management/commands/runserver.py", line 121, in inner_run
    self.check(display_num_errors=True)
  File "/usr/lib/python2.7/site-packages/django/core/management/base.py", line 374, in check
    include_deployment_checks=include_deployment_checks,
  File "/usr/lib/python2.7/site-packages/django/core/management/base.py", line 361, in _run_checks
    return checks.run_checks(**kwargs)
  File "/usr/lib/python2.7/site-packages/django/core/checks/registry.py", line 81, in run_checks
    new_errors = check(app_configs=app_configs)
  File "/usr/lib/python2.7/site-packages/django/core/checks/urls.py", line 14, in check_url_config
    return check_resolver(resolver)
  File "/usr/lib/python2.7/site-packages/django/core/checks/urls.py", line 24, in check_resolver
    for pattern in resolver.url_patterns:
  File "/usr/lib/python2.7/site-packages/django/utils/functional.py", line 35, in __get__
    res = instance.__dict__[self.name] = self.func(instance)
  File "/usr/lib/python2.7/site-packages/django/urls/resolvers.py", line 313, in url_patterns
    patterns = getattr(self.urlconf_module, "urlpatterns", self.urlconf_module)
  File "/usr/lib/python2.7/site-packages/django/utils/functional.py", line 35, in __get__
    res = instance.__dict__[self.name] = self.func(instance)
  File "/usr/lib/python2.7/site-packages/django/urls/resolvers.py", line 306, in urlconf_module
    return import_module(self.urlconf_name)
  File "/usr/lib64/python2.7/importlib/__init__.py", line 37, in import_module
    __import__(name)
  File "/home/logAnalyse/logAnalyse/logAnalyse/urls.py", line 19, in <module>
    from . import gitlog
  File "/home/logAnalyse/logAnalyse/logAnalyse/gitlog.py", line 273
    log = r.git.log('--pretty=format:|%H|%h|%ae|%an|%ce|%cn|%at|%ad|', "--numstat", "--after='+"last_time"+'", "-n 1000",skip)
                                                                                                        ^
SyntaxError: invalid syntax
Unhandled exception in thread started by <function wrapper at 0x7fac61ce1e60>
Traceback (most recent call last):
  File "/usr/lib/python2.7/site-packages/django/utils/autoreload.py", line 226, in wrapper
    fn(*args, **kwargs)
  File "/usr/lib/python2.7/site-packages/django/core/management/commands/runserver.py", line 113, in inner_run
    autoreload.raise_last_exception()
  File "/usr/lib/python2.7/site-packages/django/utils/autoreload.py", line 249, in raise_last_exception
    six.reraise(*_exception)
  File "/usr/lib/python2.7/site-packages/django/utils/autoreload.py", line 226, in wrapper
    fn(*args, **kwargs)
  File "/usr/lib/python2.7/site-packages/django/__init__.py", line 27, in setup
    apps.populate(settings.INSTALLED_APPS)
  File "/usr/lib/python2.7/site-packages/django/apps/registry.py", line 108, in populate
    app_config.import_models(all_models)
  File "/usr/lib/python2.7/site-packages/django/apps/config.py", line 199, in import_models
    self.models_module = import_module(models_module_name)
  File "/usr/lib64/python2.7/importlib/__init__.py", line 37, in import_module
    __import__(name)
  File "/home/logAnalyse/logAnalyse/logAnalyse/models.py", line 26, in <module>
    class GitLog(model.Model):
NameError: name 'model' is not defined
Unhandled exception in thread started by <function wrapper at 0x7f0f14c77de8>
Traceback (most recent call last):
  File "/usr/lib/python2.7/site-packages/django/utils/autoreload.py", line 226, in wrapper
    fn(*args, **kwargs)
  File "/usr/lib/python2.7/site-packages/django/core/management/commands/runserver.py", line 113, in inner_run
    autoreload.raise_last_exception()
  File "/usr/lib/python2.7/site-packages/django/utils/autoreload.py", line 249, in raise_last_exception
    six.reraise(*_exception)
  File "/usr/lib/python2.7/site-packages/django/utils/autoreload.py", line 226, in wrapper
    fn(*args, **kwargs)
  File "/usr/lib/python2.7/site-packages/django/__init__.py", line 27, in setup
    apps.populate(settings.INSTALLED_APPS)
  File "/usr/lib/python2.7/site-packages/django/apps/registry.py", line 108, in populate
    app_config.import_models(all_models)
  File "/usr/lib/python2.7/site-packages/django/apps/config.py", line 199, in import_models
    self.models_module = import_module(models_module_name)
  File "/usr/lib64/python2.7/importlib/__init__.py", line 37, in import_module
    __import__(name)
  File "/home/logAnalyse/logAnalyse/logAnalyse/models.py", line 26, in <module>
    class GitLog(model.Model):
NameError: name 'model' is not defined
Unhandled exception in thread started by <function wrapper at 0x7f0eb2617de8>
Traceback (most recent call last):
  File "/usr/lib/python2.7/site-packages/django/utils/autoreload.py", line 226, in wrapper
    fn(*args, **kwargs)
  File "/usr/lib/python2.7/site-packages/django/core/management/commands/runserver.py", line 113, in inner_run
    autoreload.raise_last_exception()
  File "/usr/lib/python2.7/site-packages/django/utils/autoreload.py", line 249, in raise_last_exception
    six.reraise(*_exception)
  File "/usr/lib/python2.7/site-packages/django/utils/autoreload.py", line 226, in wrapper
    fn(*args, **kwargs)
  File "/usr/lib/python2.7/site-packages/django/__init__.py", line 27, in setup
    apps.populate(settings.INSTALLED_APPS)
  File "/usr/lib/python2.7/site-packages/django/apps/registry.py", line 108, in populate
    app_config.import_models(all_models)
  File "/usr/lib/python2.7/site-packages/django/apps/config.py", line 199, in import_models
    self.models_module = import_module(models_module_name)
  File "/usr/lib64/python2.7/importlib/__init__.py", line 37, in import_module
    __import__(name)
  File "/home/logAnalyse/logAnalyse/logAnalyse/models.py", line 26, in <module>
    class GitLog(model.Model):
NameError: name 'model' is not defined
Unhandled exception in thread started by <function wrapper at 0x7f8843b72de8>
Traceback (most recent call last):
  File "/usr/lib/python2.7/site-packages/django/utils/autoreload.py", line 226, in wrapper
    fn(*args, **kwargs)
  File "/usr/lib/python2.7/site-packages/django/core/management/commands/runserver.py", line 113, in inner_run
    autoreload.raise_last_exception()
  File "/usr/lib/python2.7/site-packages/django/utils/autoreload.py", line 249, in raise_last_exception
    six.reraise(*_exception)
  File "/usr/lib/python2.7/site-packages/django/utils/autoreload.py", line 226, in wrapper
    fn(*args, **kwargs)
  File "/usr/lib/python2.7/site-packages/django/__init__.py", line 27, in setup
    apps.populate(settings.INSTALLED_APPS)
  File "/usr/lib/python2.7/site-packages/django/apps/registry.py", line 108, in populate
    app_config.import_models(all_models)
  File "/usr/lib/python2.7/site-packages/django/apps/config.py", line 199, in import_models
    self.models_module = import_module(models_module_name)
  File "/usr/lib64/python2.7/importlib/__init__.py", line 37, in import_module
    __import__(name)
  File "/home/logAnalyse/logAnalyse/logAnalyse/models.py", line 26, in <module>
    class GitLogLoad(model.Model):
NameError: name 'model' is not defined
Unhandled exception in thread started by <function wrapper at 0x7f93dc8dfde8>
Traceback (most recent call last):
  File "/usr/lib/python2.7/site-packages/django/utils/autoreload.py", line 226, in wrapper
    fn(*args, **kwargs)
  File "/usr/lib/python2.7/site-packages/django/core/management/commands/runserver.py", line 113, in inner_run
    autoreload.raise_last_exception()
  File "/usr/lib/python2.7/site-packages/django/utils/autoreload.py", line 249, in raise_last_exception
    six.reraise(*_exception)
  File "/usr/lib/python2.7/site-packages/django/utils/autoreload.py", line 226, in wrapper
    fn(*args, **kwargs)
  File "/usr/lib/python2.7/site-packages/django/__init__.py", line 27, in setup
    apps.populate(settings.INSTALLED_APPS)
  File "/usr/lib/python2.7/site-packages/django/apps/registry.py", line 108, in populate
    app_config.import_models(all_models)
  File "/usr/lib/python2.7/site-packages/django/apps/config.py", line 199, in import_models
    self.models_module = import_module(models_module_name)
  File "/usr/lib64/python2.7/importlib/__init__.py", line 37, in import_module
    __import__(name)
  File "/home/logAnalyse/logAnalyse/logAnalyse/models.py", line 26, in <module>
    class GitLogLoad(model.Model):
NameError: name 'model' is not defined
